Workbook

Sheet Simulação Imp-fluxopgto
B2: Premissas | E2: Fluxo pagamento
B3: Assinante Adimplentes | C3: 58000 | E3: Mês | F3: Non compete PF | G3: Intangivel | H3: Imobilizado | I3: Divida Aquisições | J3: FTTP | K3: Fee Advisor | L3: Total
B4: Valor/Assinante | C4: 2850 | E4: Entrada | F4: =+C12/4 -> 12397500 | G4: =+C6-F4-K4-H4 -> 25722500 | H4: 25000000 | I4: 0 | K4: 3000000 | L4: =SUM(F4:K4) -> 66120000
B5: Valor | C5: =+C4*C3 -> 165300000 | E5: 46235 | I5: =+'Pgto Sellers'!G13 -> 0 | L5: =SUM(F5:K5) -> 0
B6: Entrada -40% | C6: =+C5*0.4 -> 66120000 | E6: 46266 | I6: =+'Pgto Sellers'!H13 -> 923769.7 | L6: =SUM(F6:K6) -> 923769.7
B7: Pgto sellers | C7: =+SUM(I5:I24) -> 9418236.6 | E7: 46296 | I7: =+'Pgto Sellers'!I13 -> 1003778 | J7: =+($C$8/16-SUM(I5:I6))-I7 -> 4271202.3 | L7: =SUM(F7:K7) -> 5274980.3
B8: Saldo | C8: =+C5-C6 -> 99180000 | E8: 46327 | I8: =+'Pgto Sellers'!J13 -> 923769.7 | L8: =SUM(F8:K8) -> 923769.7
B9: Fee advisor | C9: =+C5*0.03 -> 4959000 | E9: 46357 | I9: =+'Pgto Sellers'!K13 -> 691867.72 | L9: =SUM(F9:K9) -> 691867.72
B10: Tributação | E10: 46388 | I10: =+'Pgto Sellers'!L13 -> 611883.89 | J10: =+($C$8/16-SUM(I8:I9))-SUM(F10:I10) -> 3971228.7 | L10: =SUM(F10:K10) -> 4583112.6
B11: Carteira de Clientes/Ativos de rede | C11: =+C5-C12-C13 -> 95710000 | E11: 46419 | I11: =+'Pgto Sellers'!M13 -> 689566.13 | L11: =SUM(F11:K11) -> 689566.13
B12: Non Compete | C12: =+C5*0.3 -> 49590000 | E12: 46447 | I12: =+'Pgto Sellers'!N13 -> 595386.97 | L12: =SUM(F12:K12) -> 595386.97
B13: FTTP | C13: 20000000 | E13: 46478 | I13: =+'Pgto Sellers'!O13 -> 673786.03 | J13: =+($C$8/16-SUM(I11:I12))-SUM(F13:I13) -> 4240010.9 | L13: =SUM(F13:K13) -> 4913796.9
B14: total | C14: =SUM(C11:C13) -> 165300000 | E14: 46508 | I14: =+'Pgto Sellers'!P13 -> 356239.31 | L14: =SUM(F14:K14) -> 356239.31
E15: 46539 | I15: =+'Pgto Sellers'!Q13 -> 356247.64 | L15: =SUM(F15:K15) -> 356247.64
B16: Imposto | C16: =+C13*0.1534 -> 3068000 | E16: 46569 | I16: =+'Pgto Sellers'!R13 -> 356239.31 | J16: =+($C$8/16-SUM(I14:I15))-SUM(F16:I16) -> 5130023.7 | L16: =SUM(F16:K16) -> 5486263.1
B17: Saldo Liquido | C17: =+C5-C16-C21 -> 157273000 | E17: 46600 | I17: =+'Pgto Sellers'!S13 -> 356247.64 | L17: =SUM(F17:K17) -> 356247.64
B18: Imobilizado | C18: 25000000 | E18: 46631 | I18: =+'Pgto Sellers'!T13 -> 353556.57 | L18: =SUM(F18:K18) -> 353556.57
B19: Intangivel Balanço | C19: 32000000 | E19: 46661 | I19: =+'Pgto Sellers'!U13 -> 353564.94 | L19: =SUM(F19:K19) -> 353564.94
B20: Laudo | C20: 35000000 | E20: 46692 | I20: =+'Pgto Sellers'!V13 -> 236898.2 | L20: =SUM(F20:K20) -> 236898.2
B21: Comissão - Dedutivel | C21: =+C5*3% -> 4959000 | E21: 46722 | I21: =+'Pgto Sellers'!W13 -> 236898.2 | L21: =SUM(F21:K21) -> 236898.2
C22: =SUM(C18:C21) -> 96959000 | E22: 46753 | I22: =+'Pgto Sellers'!X13 -> 234424.09 | L22: =SUM(F22:K22) -> 234424.09
E23: 46784 | I23: =+'Pgto Sellers'!Y13 -> 232056.3 | L23: =SUM(F23:K23) -> 232056.3
C24: =+C6-C18 -> 41120000 | E24: 46813 | I24: =+'Pgto Sellers'!Z13 -> 232056.3 | L24: =SUM(F24:K24) -> 232056.3
E25: 46844 | I25: =+'Pgto Sellers'!AA13 -> 232056.3 | L25: =SUM(F25:K25) -> 232056.3
E26: 46874 | I26: =+'Pgto Sellers'!AB13 -> 151754.61 | L26: =SUM(F26:K26) -> 151754.61
E27: 46905 | I27: =+'Pgto Sellers'!AC13 -> 151754.61 | L27: =SUM(F27:K27) -> 151754.61
E28: 46935 | F28: =+F4 -> 12397500 | G28: =++$C$8/4-SUM(I17:I28)-J28-F28-K28 -> 6433943.2 | I28: =+'Pgto Sellers'!AD13 -> 151754.61 | J28: =+C13-J16-J13-J10-J7 -> 2387534.4 | K28: =+($C$9-$K$4)/3 -> 653000 | L28: =SUM(F28:K28) -> 22023732
E29: 46966 | I29: =+'Pgto Sellers'!AE13 -> 151754.61 | L29: =SUM(F29:K29) -> 151754.61
E30: 46997 | I30: =+'Pgto Sellers'!AF13 -> 151754.61 | L30: =SUM(F30:K30) -> 151754.61
E31: 47027 | I31: =+'Pgto Sellers'!AG13 -> 151754.61 | L31: =SUM(F31:K31) -> 151754.61
E32: 47058 | I32: =+'Pgto Sellers'!AH13 -> 151754.61 | L32: =SUM(F32:K32) -> 151754.61
E33: 47088 | I33: =+'Pgto Sellers'!AI13 -> 151754.61 | L33: =SUM(F33:K33) -> 151754.61
E34: 47119 | I34: =+'Pgto Sellers'!AJ13 -> 151754.61 | L34: =SUM(F34:K34) -> 151754.61
E35: 47150 | I35: =+'Pgto Sellers'!AK13 -> 151754.61 | L35: =SUM(F35:K35) -> 151754.61
E36: 47178 | I36: =+'Pgto Sellers'!AL13 -> 151754.61 | L36: =SUM(F36:K36) -> 151754.61
E37: 47209 | I37: =+'Pgto Sellers'!AM13 -> 151754.61 | L37: =SUM(F37:K37) -> 151754.61
E38: 47239 | I38: =+'Pgto Sellers'!AN13 -> 151754.61 | L38: =SUM(F38:K38) -> 151754.61
E39: 47270 | I39: =+'Pgto Sellers'!AO13 -> 151754.61 | L39: =SUM(F39:K39) -> 151754.61
E40: 47300 | F40: =+F28 -> 12397500 | G40: =++$C$8/4-SUM(I29:I40)-J40-F40-K40 -> 9923444.7 | I40: =+'Pgto Sellers'!AP13 -> 151754.61 | K40: =+($C$9-$K$4)/3 -> 653000 | L40: =SUM(F40:K40) -> 23125699
E41: 47331 | I41: =+'Pgto Sellers'!AQ13 -> 151754.61 | L41: =SUM(F41:K41) -> 151754.61
...

Sheet Pgto Sellers
A1: Tipo de Pagamento | B1: Favorecido | C1: Banco | D1: Agência | E1: Conta | F1: CNPJ | G1: 46235 | H1: 46266 | I1: 46296 | J1: 46327 | K1: 46357 | L1: 46388 | M1: 46419 | N1: 46447 | O1: 46478 | P1: 46508 | Q1: 46539 | R1: 46569 | S1: 46600 | T1: 46631 | U1: 46661 | V1: 46692 | W1: 46722 | X1: 46753 | Y1: 46784 | Z1: 46813 | AA1: 46844 | AB1: 46874 | AC1: 46905 | AD1: 46935 | AE1: 46966 | AF1: 46997 | AG1: 47027 | AH1: 47058 | AI1: 47088 | AJ1: 47119 | AK1: 47150 | AL1: 47178 | AM1: 47209 | AN1: 47239 | AO1: 47270 | AP1: 47300 | AQ1: 47331 | AR1: 47362 | AS1: 47392 | AT1: 47423 | AU1: 47453 | AV1: 47484 | AW1: 47515 | AX1: 47543 | AY1: 47574 | AZ1: 47604 | BA1: 47635 | BB1: 47665 | BC1: Total Geral
A2: Bsb Internet | B2: BSB INTERNERT | C2: 756 | D2: 3054 | E2: 31759-4 | F2: 51.352.661/0001-17 | G2: 0 | H2: 0 | I2: 116666.66 | J2: 0 | K2: 116666.66 | L2: 0 | M2: 116666.66 | N2: 0 | O2: 116666.66 | P2: 0 | Q2: 116666.66 | R2: 0 | S2: 116666.66 | T2: 0 | U2: 116666.74 | V2: 0 | W2: 0 | X2: 0 | Y2: 0 | Z2: 0 | AA2: 0 | AB2: 0 | AC2: 0 | AD2: 0 | AE2: 0 | AF2: 0 | AG2: 0 | AH2: 0 | AI2: 0 | AJ2: 0 | AK2: 0 | AL2: 0 | AM2: 0 | AN2: 0 | AO2: 0 | AP2: 0 | AQ2: 0 | AR2: 0 | AS2: 0 | AT2: 0 | AU2: 0 | AV2: 0 | AW2: 0 | AX2: 0 | AY2: 0 | AZ2: 0 | BA2: 0 | BB2: 0 | BC2: =SUM(H2:BB2) -> 816666.7
A3: Cev Fibra Comercio e Servicos de Comunicacao Ltda | B3: Vec Fibra | C3: 33 | D3: 1181 | E3: 13001338-6 | F3: 12.239.348/0001-15 | G3: 0 | H3: 351670.07 | I3: 351670.07 | J3: 351670.07 | K3: 39759.76 | L3: 39784.26 | M3: 37458.17 | N3: 23287.34 | O3: 21678.07 | P3: 7524.68 | Q3: 7524.68 | R3: 7524.68 | S3: 7524.68 | T3: 4841.9 | U3: 4841.9 | V3: 4841.9 | W3: 4841.9 | X3: 2367.79 | Y3: 0 | Z3: 0 | AA3: 0 | AB3: 0 | AC3: 0 | AD3: 0 | AE3: 0 | AF3: 0 | AG3: 0 | AH3: 0 | AI3: 0 | AJ3: 0 | AK3: 0 | AL3: 0 | AM3: 0 | AN3: 0 | AO3: 0 | AP3: 0 | AQ3: 0 | AR3: 0 | AS3: 0 | AT3: 0 | AU3: 0 | AV3: 0 | AW3: 0 | AX3: 0 | AY3: 0 | AZ3: 0 | BA3: 0 | BB3: 0 | BC3: =SUM(H3:BB3) -> 1268811.9
A4: Giptelecom | B4: Ediene Oliveira de Araújo | C4: 1 | D4: 221 | E4: 11468-5 | F4: 689.754.811-15 | G4: 0 | H4: 1190.07 | I4: 1190.07 | J4: 1190.07 | K4: 1190.07 | L4: 1190.07 | M4: 1190.07 | N4: 1190.07 | O4: 1190.07 | P4: 1190.07 | Q4: 1190.07 | R4: 1190.07 | S4: 1190.07 | T4: 1190.07 | U4: 1190.07 | V4: 1190.07 | W4: 1190.07 | X4: 1190.07 | Y4: 1190.07 | Z4: 1190.07 | AA4: 1190.07 | AB4: 0 | AC4: 0 | AD4: 0 | AE4: 0 | AF4: 0 | AG4: 0 | AH4: 0 | AI4: 0 | AJ4: 0 | AK4: 0 | AL4: 0 | AM4: 0 | AN4: 0 | AO4: 0 | AP4: 0 | AQ4: 0 | AR4: 0 | AS4: 0 | AT4: 0 | AU4: 0 | AV4: 0 | AW4: 0 | AX4: 0 | AY4: 0 | AZ4: 0 | BA4: 0 | BB4: 0 | BC4: =SUM(H4:BB4) -> 23801.4
B5: Victor Júlio dos Santos | C5: 756 | D5: 4033 | E5: 260013-7 | F5: 186.441.438-32 | G5: 0 | H5: 22376.07 | I5: 22376.07 | J5: 22376.07 | K5: 22376.07 | L5: 22376.07 | M5: 22376.07 | N5: 22376.07 | O5: 22376.07 | P5: 22376.07 | Q5: 22376.07 | R5: 22376.07 | S5: 22376.07 | T5: 22376.07 | U5: 22376.07 | V5: 22376.07 | W5: 22376.07 | X5: 22376.07 | Y5: 22376.07 | Z5: 22376.07 | AA5: 22376.07 | AB5: 0 | AC5: 0 | AD5: 0 | AE5: 0 | AF5: 0 | AG5: 0 | AH5: 0 | AI5: 0 | AJ5: 0 | AK5: 0 | AL5: 0 | AM5: 0 | AN5: 0 | AO5: 0 | AP5: 0 | AQ5: 0 | AR5: 0 | AS5: 0 | AT5: 0 | AU5: 0 | AV5: 0 | AW5: 0 | AX5: 0 | AY5: 0 | AZ5: 0 | BA5: 0 | BB5: 0 | BC5: =SUM(H5:BB5) -> 447521.4
B6: Sandro Gomes de Araújo | C6: 748 | D6: 3953 | E6: 33927-0 | F6: 486.011.441-87 | G6: 0 | H6: 10710.64 | I6: 10710.64 | J6: 10710.64 | K6: 10710.64 | L6: 10710.64 | M6: 10710.64 | N6: 10710.64 | O6: 10710.64 | P6: 10710.64 | Q6: 10710.64 | R6: 10710.64 | S6: 10710.64 | T6: 10710.64 | U6: 10710.64 | V6: 10710.64 | W6: 10710.64 | X6: 10710.64 | Y6: 10710.64 | Z6: 10710.64 | AA6: 10710.64 | AB6: 0 | AC6: 0 | AD6: 0 | AE6: 0 | AF6: 0 | AG6: 0 | AH6: 0 | AI6: 0 | AJ6: 0 | AK6: 0 | AL6: 0 | AM6: 0 | AN6: 0 | AO6: 0 | AP6: 0 | AQ6: 0 | AR6: 0 | AS6: 0 | AT6: 0 | AU6: 0 | AV6: 0 | AW6: 0 | AX6: 0 | AY6: 0 | AZ6: 0 | BA6: 0 | BB6: 0 | BC6: =SUM(H6:BB6) -> 214212.8
B7: Pedro Humberto alves Albenaz | C7: 237 | D7: 987 | E7: 27557-3 | F7: 477.725.496-87 | G7: 0 | H7: 23648.84 | I7: 23648.84 | J7: 23648.84 | K7: 23648.84 | L7: 23648.84 | M7: 23648.84 | N7: 23648.84 | O7: 23648.84 | P7: 23648.84 | Q7: 23648.84 | R7: 23648.84 | S7: 23648.84 | T7: 23648.84 | U7: 23648.84 | V7: 23648.84 | W7: 23648.84 | X7: 23648.84 | Y7: 23648.84 | Z7: 23648.84 | AA7: 23648.84 | AB7: 0 | AC7: 0 | AD7: 0 | AE7: 0 | AF7: 0 | AG7: 0 | AH7: 0 | AI7: 0 | AJ7: 0 | AK7: 0 | AL7: 0 | AM7: 0 | AN7: 0 | AO7: 0 | AP7: 0 | AQ7: 0 | AR7: 0 | AS7: 0 | AT7: 0 | AU7: 0 | AV7: 0 | AW7: 0 | AX7: 0 | AY7: 0 | AZ7: 0 | BA7: 0 | BB7: 0 | BC7: =SUM(H7:BB7) -> 472976.8
B8: Nair Soares Gontijo | C8: 756 | D8: 3179 | E8: 24864-9 | F8: 013.382.796-88 | G8: 0 | H8: 22376.07 | I8: 22376.07 | J8: 22376.07 | K8: 22376.07 | L8: 22376.07 | M8: 22376.07 | N8: 22376.07 | O8: 22376.07 | P8: 22376.07 | Q8: 22376.07 | R8: 22376.07 | S8: 22376.07 | T8: 22376.07 | U8: 22376.07 | V8: 22376.07 | W8: 22376.07 | X8: 22376.07 | Y8: 22376.07 | Z8: 22376.07 | AA8: 22376.07 | AB8: 0 | AC8: 0 | AD8: 0 | AE8: 0 | AF8: 0 | AG8: 0 | AH8: 0 | AI8: 0 | AJ8: 0 | AK8: 0 | AL8: 0 | AM8: 0 | AN8: 0 | AO8: 0 | AP8: 0 | AQ8: 0 | AR8: 0 | AS8: 0 | AT8: 0 | AU8: 0 | AV8: 0 | AW8: 0 | AX8: 0 | AY8: 0 | AZ8: 0 | BA8: 0 | BB8: 0 | BC8: =SUM(H8:BB8) -> 447521.4
A9: Hilan Telecom Ltda | B9: Hilan Telecom Ltda | C9: 748 | D9: 3953 | E9: 118152-1 | F9: 31.390.568/0001-90 | G9: 0 | H9: 245737.9 | I9: 245737.9 | J9: 245737.9 | K9: 245737.9 | L9: 245737.9 | M9: 245737.9 | N9: 245737.9 | O9: 245737.9 | P9: 0 | Q9: 0 | R9: 0 | S9: 0 | T9: 0 | U9: 0 | V9: 0 | W9: 0 | X9: 0 | Y9: 0 | Z9: 0 | AA9: 0 | AB9: 0 | AC9: 0 | AD9: 0 | AE9: 0 | AF9: 0 | AG9: 0 | AH9: 0 | AI9: 0 | AJ9: 0 | AK9: 0 | AL9: 0 | AM9: 0 | AN9: 0 | AO9: 0 | AP9: 0 | AQ9: 0 | AR9: 0 | AS9: 0 | AT9: 0 | AU9: 0 | AV9: 0 | AW9: 0 | AX9: 0 | AY9: 0 | AZ9: 0 | BA9: 0 | BB9: 0 | BC9: =SUM(H9:BB9) -> 1965903.2
B10: Hilan Telecom Ltda | C10: 1 | D10: 4275 | E10: 18036-0 | F10: 31.390.568/0001-90 | G10: 0 | H10: 36658.33 | I10: 0 | J10: 36658.33 | K10: 0 | L10: 36658.33 | M10: 0 | N10: 36658.33 | O10: 0 | P10: 116658.33 | Q10: 0 | R10: 116658.33 | S10: 0 | T10: 116658.37 | U10: 0 | V10: 0 | W10: 0 | X10: 0 | Y10: 0 | Z10: 0 | AA10: 0 | AB10: 0 | AC10: 0 | AD10: 0 | AE10: 0 | AF10: 0 | AG10: 0 | AH10: 0 | AI10: 0 | AJ10: 0 | AK10: 0 | AL10: 0 | AM10: 0 | AN10: 0 | AO10: 0 | AP10: 0 | AQ10: 0 | AR10: 0 | AS10: 0 | AT10: 0 | AU10: 0 | AV10: 0 | AW10: 0 | AX10: 0 | AY10: 0 | AZ10: 0 | BA10: 0 | BB10: 0 | BC10: =SUM(H10:BB10) -> 496608.35
A11: Interfiber Telecom Ltda | B11: Leao construtora e Serviços | C11: 748 | D11: 3953 | E11: 32184-2 | F11: 27.851.023/0001-66 | G11: 0 | H11: 57647.1 | I11: 57647.1 | J11: 57647.1 | K11: 57647.1 | L11: 57647.1 | M11: 57647.1 | N11: 57647.1 | O11: 57647.1 | P11: 0 | Q11: 0 | R11: 0 | S11: 0 | T11: 0 | U11: 0 | V11: 0 | W11: 0 | X11: 0 | Y11: 0 | Z11: 0 | AA11: 0 | AB11: 0 | AC11: 0 | AD11: 0 | AE11: 0 | AF11: 0 | AG11: 0 | AH11: 0 | AI11: 0 | AJ11: 0 | AK11: 0 | AL11: 0 | AM11: 0 | AN11: 0 | AO11: 0 | AP11: 0 | AQ11: 0 | AR11: 0 | AS11: 0 | AT11: 0 | AU11: 0 | AV11: 0 | AW11: 0 | AX11: 0 | AY11: 0 | AZ11: 0 | BA11: 0 | BB11: 0 | BC11: =SUM(H11:BB11) -> 461176.8
A12: Saida Sócio | B12: Vicente Araújo Lima Filho | C12: 33 | D12: 1723 | E12: 01003754-4 | F12: 934.896.413-53 | G12: 0 | H12: 151754.61 | I12: 151754.61 | J12: 151754.61 | K12: 151754.61 | L12: 151754.61 | M12: 151754.61 | N12: 151754.61 | O12: 151754.61 | P12: 151754.61 | Q12: 151754.61 | R12: 151754.61 | S12: 151754.61 | T12: 151754.61 | U12: 151754.61 | V12: 151754.61 | W12: 151754.61 | X12: 151754.61 | Y12: 151754.61 | Z12: 151754.61 | AA12: 151754.61 | AB12: 151754.61 | AC12: 151754.61 | AD12: 151754.61 | AE12: 151754.61 | AF12: 151754.61 | AG12: 151754.61 | AH12: 151754.61 | AI12: 151754.61 | AJ12: 151754.61 | AK12: 151754.61 | AL12: 151754.61 | AM12: 151754.61 | AN12: 151754.61 | AO12: 151754.61 | AP12: 151754.61 | AQ12: 151754.61 | AR12: 151754.61 | AS12: 151754.61 | AT12: 151754.61 | AU12: 151754.61 | AV12: 151754.61 | AW12: 151754.61 | AX12: 151754.61 | AY12: 151754.61 | AZ12: 151754.61 | BA12: 151754.61 | BB12: 151754.61 | BC12: =SUM(H12:BB12) -> 7132466.6
A13: Total Mensal | G13: =SUM(G2:G12) -> 0 | H13: =SUM(H2:H12) -> 923769.7 | I13: =SUM(I2:I12) -> 1003778 | J13: =SUM(J2:J12) -> 923769.7 | K13: =SUM(K2:K12) -> 691867.72 | L13: =SUM(L2:L12) -> 611883.89 | M13: =SUM(M2:M12) -> 689566.13 | N13: =SUM(N2:N12) -> 595386.97 | ... BC13: =SUM(BC2:BC12) -> 13747667
