Workbook

Sheet Simulação Imp-fluxopgto
B2: Premissas | E2: Fluxo pagamento | H2: fttp | J2: tirar do intang
B3: Assinante Adimplentes | C3: 58000 | E3: Mês | F3: Intangivel | G3: Imobilizado | H3: Divida Aquisições | I3: FTTP | J3: Fee Advisor | K3: Total
B4: Valor/Assinante | C4: 2850 | E4: Entrada | F4: =+C6-G4-H4-I4-J4 -> 7716927.2 | G4: =+C17 -> 28762281 | H4: 0 | I4: =+C29*0.5+C28*0.3+C30*0.3 -> 26640792 | J4: 3000000 | K4: =SUM(F4:J4) -> 66120000
B5: Valor | C5: =+C4*C3 -> 165300000 | E5: 46235 | H5: =+'Pgto Sellers'!B7 -> 0 | K5: =SUM(F5:J5) -> 0
B6: Entrada -40% | C6: =+C5*0.4 -> 66120000 | E6: 46266 | H6: =+'Pgto Sellers'!C7 -> 769015.09 | K6: =SUM(F6:J6) -> 769015.09 | M6: R$ por HC | N6: 50 | O6: >> preço proximo do mercado
B7: Pgto sellers | C7: =+SUM(H5:H24) -> 6531899.1 | E7: 46296 | H7: =+'Pgto Sellers'!D7 -> 852023.42 | I7: =+($C$8/16-SUM(H5:H6))-H7 -> 4577711.5 | K7: =SUM(F7:J7) -> 5429734.9 | M7: HC | N7: 62439
B8: Saldo | C8: =+C5-C6 -> 99180000 | E8: 46327 | H8: =+'Pgto Sellers'!E7 -> 772015.09 | K8: =SUM(F8:J8) -> 772015.09 | M8: Meses | N8: 12
B9: Fee advisor | C9: =+C5*0.03 -> 4959000 | E9: 46357 | H9: =+'Pgto Sellers'!F7 -> 540113.11 | K9: =SUM(F9:J9) -> 540113.11
B10: Tributação | E10: 46388 | H10: =+'Pgto Sellers'!G7 -> 460129.28 | I10: =+($C$8/16-SUM(H8:H9))-SUM(F10:H10) -> 4426492.5 | K10: =SUM(F10:J10) -> 4886621.8 | M10: Valor total do FTTP | N10: =PRODUCT(N6:N8)/10^3 -> 37463.4
B11: Carteira de Clientes/Ativos de rede | C11: =+C20 -> 1.0625736e+08 | E11: 46419 | H11: =+'Pgto Sellers'!H7 -> 537811.52 | K11: =SUM(F11:J11) -> 537811.52
B12: FTTP | C12: =+C5-C11 -> 59042640 | E12: 46447 | H12: =+'Pgto Sellers'!I7 -> 443632.36 | K12: =SUM(F12:J12) -> 443632.36 | M12: atendimentos por mês | N12: 500
B13: total | C13: =SUM(C11:C12) -> 165300000 | E13: 46478 | H13: =+'Pgto Sellers'!J7 -> 522031.42 | I13: =+($C$8/16-SUM(H11:H12))-SUM(F13:H13) -> 4695274.7 | K13: =SUM(F13:J13) -> 5217306.1 | M13: preço atendimento | N13: 200 | O13: >> preço no contrato
E14: 46508 | H14: =+'Pgto Sellers'!K7 -> 204484.7 | K14: =SUM(F14:J14) -> 204484.7 | M14: meses | N14: 12
E15: 46539 | H15: =+'Pgto Sellers'!L7 -> 204493.03 | K15: =SUM(F15:J15) -> 204493.03
E16: 46569 | H16: =+'Pgto Sellers'!M7 -> 204484.7 | I16: =+($C$8/16-SUM(H14:H15))-SUM(F16:H16) -> 5585287.6 | K16: =SUM(F16:J16) -> 5789772.3 | M16: fator de prontidão | N16: 4
B17: . Imobilizado Onitel Telecom | C17: 28762281 | E17: 46600 | H17: =+'Pgto Sellers'!N7 -> 204493.03 | K17: =SUM(F17:J17) -> 204493.03
B18: . Intangivel Onitel Telecom | C18: 50137838 | E18: 46631 | H18: =+'Pgto Sellers'!O7 -> 201801.96 | K18: =SUM(F18:J18) -> 201801.96 | M18: Valor do take or pay atendimento | N18: =PRODUCT(N12:N14)/10^3*N16 -> 4800
B19: . Intangivel Onitel Serviços | C19: 27357241 | E19: 46661 | H19: =+'Pgto Sellers'!P7 -> 201810.33 | K19: =SUM(F19:J19) -> 201810.33
B20: Total | C20: =++C22+C17+C18+C19 -> 1.0625736e+08 | E20: 46692 | H20: =+'Pgto Sellers'!Q7 -> 85143.59 | K20: =SUM(F20:J20) -> 85143.59 | M20: HC | N20: =N7 -> 62439
E21: 46722 | H21: =+'Pgto Sellers'!R7 -> 85143.59 | K21: =SUM(F21:J21) -> 85143.59 | M21: preço setup | N21: =N23/N20*10^3 -> 268.73013 | O21: >> mão de obra + drop pra uma instalação
C22: =C18/SUM(C18:C19) -> 0.64698093 | E22: 46753 | H22: =+'Pgto Sellers'!S7 -> 82669.48 | K22: =SUM(F22:J22) -> 82669.48
B23: =C3-C23 -> 20475.106 | C23: =C22*C3 -> 37524.894 | E23: 46784 | H23: =+'Pgto Sellers'!T7 -> 80301.69 | K23: =SUM(F23:J23) -> 80301.69 | M23: Valor total do setup | N23: =(I54/10^3)-SUM(N18,N10) -> 16779.24
E24: 46813 | H24: =+'Pgto Sellers'!U7 -> 80301.69 | K24: =SUM(F24:J24) -> 80301.69
B25: tributo | C25: =++C12*0.1534 -> 9057141 | E25: 46844 | H25: =+'Pgto Sellers'!V7 -> 80301.69 | K25: =SUM(F25:J25) -> 80301.69 | M25: Total | N25: =SUM(N23,N18,N10) -> 59042.64
B26: FTTP | C26: 62000 | E26: 46874 | H26: =+'Pgto Sellers'!W7 -> 0 | K26: =SUM(F26:J26) -> 0
B27: .PORTA | C27: 15 | E27: 46905 | H27: =+'Pgto Sellers'!X7 -> 0 | K27: =SUM(F27:J27) -> 0
B28: . Valor porta ILUMINADA | C28: =+C27*12*C26 -> 11160000 | E28: 46935 | F28: =++$C$8/4-SUM(H17:H28)-I28-J28 -> 9922951 | H28: =+'Pgto Sellers'!Y7 -> 0 | I28: =(C12-SUM(I4:I27)) -> 13117082 | J28: =+($C$9-$J$4)/3 -> 653000 | K28: =SUM(F28:J28) -> 23693033
B29: . Setup rede | C29: =C31-C28-C30 -> 44640000 | E29: 46966 | H29: =+'Pgto Sellers'!Z7 -> 0 | K29: =SUM(F29:J29) -> 0
B30: . Suporte N3 | C30: 3242640.3 | E30: 46997 | H30: =+'Pgto Sellers'!AA7 -> 0 | K30: =SUM(F30:J30) -> 0
C31: 59042640 | E31: 47027 | H31: =+'Pgto Sellers'!AB7 -> 0 | K31: =SUM(F31:J31) -> 0
E32: 47058 | H32: =+'Pgto Sellers'!AC7 -> 0 | K32: =SUM(F32:J32) -> 0
E33: 47088 | H33: =+'Pgto Sellers'!AD7 -> 0 | K33: =SUM(F33:J33) -> 0
E34: 47119 | H34: =+'Pgto Sellers'!AE7 -> 0 | K34: =SUM(F34:J34) -> 0
E35: 47150 | H35: =+'Pgto Sellers'!AF7 -> 0 | K35: =SUM(F35:J35) -> 0
E36: 47178 | H36: =+'Pgto Sellers'!AG7 -> 0 | K36: =SUM(F36:J36) -> 0
E37: 47209 | H37: =+'Pgto Sellers'!AH7 -> 0 | K37: =SUM(F37:J37) -> 0
E38: 47239 | H38: =+'Pgto Sellers'!AI7 -> 0 | K38: =SUM(F38:J38) -> 0
E39: 47270 | H39: =+'Pgto Sellers'!AJ7 -> 0 | K39: =SUM(F39:J39) -> 0
E40: 47300 | F40: =++$C$8/4-SUM(H29:H40)-I40-J40 -> 24142000 | H40: =+'Pgto Sellers'!AK7 -> 0 | J40: =+($C$9-$J$4)/3 -> 653000 | K40: =SUM(F40:J40) -> 24795000
E41: 47331 | H41: =+'Pgto Sellers'!AL7 -> 0 | K41: =SUM(F41:J41) -> 0
...

Sheet fluxo
K4: 0 | L4: =K4+1 -> 1 | M4: =L4+1 -> 2 | N4: =M4+1 -> 3 | O4: =N4+1 -> 4 | P4: =O4+1 -> 5 | Q4: =P4+1 -> 6 | R4: =Q4+1 -> 7 | S4: =R4+1 -> 8 | ... BG4: =BF4+1 -> 48
K5: 46204 | L5: =EDATE(K5,1) -> 46235 | M5: =EDATE(L5,1) -> 46266 | N5: =EDATE(M5,1) -> 46296 | O5: =EDATE(N5,1) -> 46327 | P5: =EDATE(O5,1) -> 46357 | Q5: =EDATE(P5,1) -> 46388 | R5: =EDATE(Q5,1) -> 46419 | S5: =EDATE(R5,1) -> 46447 | ... BG5: =EDATE(BF5,1) -> 47665
H6: Carteira | I6: total | J6: =SUM(K6:BG6) -> 74495079 | K6: ='Simulação Imp-fluxopgto'!F4 -> 7716927.2 | M6: {=TRANSPOSE('Simulação Imp-fluxopgto'!H6:H25)} -> 769015.09 | N6: 852023.42 | O6: 772015.09 | P6: 540113.11 | Q6: 460129.28 | R6: 537811.52 | S6: 443632.36 | T6: 522031.42 | U6: 204484.7 | V6: 204493.03 | W6: 204484.7 | X6: 204493.03 | Y6: 201801.96 | Z6: 201810.33 | AA6: 85143.59 | AB6: 85143.59 | AC6: 82669.48 | AD6: 80301.69 | AE6: 80301.69 | AF6: 80301.69 | AI6: ='Simulação Imp-fluxopgto'!F28+'Simulação Imp-fluxopgto'!J28 -> 10575951 | AU6: ='Simulação Imp-fluxopgto'!F40+'Simulação Imp-fluxopgto'!J40 -> 24795000 | BG6: ='Simulação Imp-fluxopgto'!F52+'Simulação Imp-fluxopgto'!J52 -> 24795000
D7: deduz daqui o fee >> | F7: ='Simulação Imp-fluxopgto'!C18/SUM('Simulação Imp-fluxopgto'!C18:C19) -> 0.64698093 | H7: Carteira | I7: Telecom | J7: =SUM(K7:BG7) -> 48196895 | K7: =K$6*$F7 -> 4992704.7 | L7: =L$6*$F7 -> 0 | M7: =M$6*$F7 -> 497538.1 | N7: =N$6*$F7 -> 551242.9 | O7: =O$6*$F7 -> 499479.04 | P7: =P$6*$F7 -> 349442.88 | Q7: =Q$6*$F7 -> 297694.87 | R7: =R$6*$F7 -> 347953.8 | ... BG7: =BG$6*$F7 -> 16041892
D8: deduz daqui o fee >> | F8: =1-F7 -> 0.35301907 | H8: Carteira | I8: Serviços | J8: =SUM(K8:BG8) -> 26298184 | K8: =K$6*$F8 -> 2724222.5 | L8: =L$6*$F8 -> 0 | M8: =M$6*$F8 -> 271476.99 | N8: =N$6*$F8 -> 300780.52 | O8: =O$6*$F8 -> 272536.05 | P8: =P$6*$F8 -> 190670.23 | Q8: =Q$6*$F8 -> 162434.41 | R8: =R$6*$F8 -> 189857.72 | ... BG8: =BG$6*$F8 -> 8753107.9
H9: Ativos | I9: Telecom | J9: =SUM(K9:BG9) -> 31762281 | K9: ='Simulação Imp-fluxopgto'!G4+'Simulação Imp-fluxopgto'!J4 -> 31762281
H10: FTTP | I10: Serviços | J10: =SUM(K10:BG10) -> 59042640 | K10: ='Simulação Imp-fluxopgto'!I4 -> 26640792 | N10: ='Simulação Imp-fluxopgto'!I7 -> 4577711.5 | Q10: ='Simulação Imp-fluxopgto'!I10 -> 4426492.5 | T10: ='Simulação Imp-fluxopgto'!I13 -> 4695274.7 | W10: ='Simulação Imp-fluxopgto'!I16 -> 5585287.6 | AI10: ='Simulação Imp-fluxopgto'!I28 -> 13117082
I11: Setup | J11: ='Simulação Imp-fluxopgto'!C29 -> 44640000 | K11: =K10 -> 26640792
I12: Porta | J12: ='Simulação Imp-fluxopgto'!C28 -> 11160000
I13: Suporte N3 | J13: ='Simulação Imp-fluxopgto'!C30 -> 3242640.3
I14: Total | J14: =SUM(J7:J10) -> 165300000 | K14: =SUM(K7:K10) -> 66120000 | L14: =SUM(L7:L10) -> 0 | M14: =SUM(M7:M10) -> 769015.09 | N14: =SUM(N7:N10) -> 5429734.9 | O14: =SUM(O7:O10) -> 772015.09 | P14: =SUM(P7:P10) -> 540113.11 | Q14: =SUM(Q7:Q10) -> 4886621.8 | ... BG14: =SUM(BG7:BG10) -> 24795000
I17: hc | J17: 58000
I18: ev/hc | J18: 2850
I19: EV | J19: =J18*J17 -> 165300000
I20: falta | J20: =J19-J14 -> 0

Sheet Pgto Sellers
A1: Tipo de Pagamento | B1: 46235 | C1: 46266 | D1: 46296 | E1: 46327 | F1: 46357 | G1: 46388 | H1: 46419 | I1: 46447 | J1: 46478 | K1: 46508 | L1: 46539 | M1: 46569 | N1: 46600 | O1: 46631 | P1: 46661 | Q1: 46692 | R1: 46722 | S1: 46753 | T1: 46784 | U1: 46813 | V1: 46844 | W1: 46874 | X1: 46905 | Y1: 46935 | Z1: 46966 | AA1: 46997 | AB1: 47027 | AC1: 47058 | AD1: 47088 | AE1: 47119 | AF1: 47150 | AG1: 47178 | AH1: 47209 | AI1: 47239 | AJ1: 47270 | AK1: 47300 | AL1: 47331 | AM1: 47362 | AN1: 47392 | AO1: 47423 | AP1: 47453 | AQ1: 47484 | AR1: 47515 | AS1: 47543 | AT1: 47574 | AU1: 47604 | AV1: 47635 | AW1: 47665 | AX1: Total Geral
A2: Bsb Internet | C2: 0 | D2: 116666.66 | E2: 0 | F2: 116666.66 | G2: 0 | H2: 116666.66 | I2: 0 | J2: 116666.66 | K2: 0 | L2: 116666.66 | M2: 0 | N2: 116666.66 | O2: 0 | P2: 116666.74 | Q2: 0 | R2: 0 | S2: 0 | T2: 0 | U2: 0 | V2: 0 | W2: 0 | X2: 0 | Y2: 0 | Z2: 0 | AA2: 0 | AB2: 0 | AC2: 0 | AD2: 0 | AE2: 0 | AF2: 0 | AG2: 0 | AH2: 0 | AI2: 0 | AJ2: 0 | AK2: 0 | AL2: 0 | AM2: 0 | AN2: 0 | AO2: 0 | AP2: 0 | AQ2: 0 | AR2: 0 | AS2: 0 | AT2: 0 | AU2: 0 | AV2: 0 | AW2: 0 | AX2: =SUM(B2:AW2) -> 816666.7
A3: Cev Fibra Comercio e Servicos de Comunicacao Ltda | C3: 351670.07 | D3: 351670.07 | E3: 351670.07 | F3: 39759.76 | G3: 39784.26 | H3: 37458.17 | I3: 23287.34 | J3: 21678.07 | K3: 7524.68 | L3: 7524.68 | M3: 7524.68 | N3: 7524.68 | O3: 4841.9 | P3: 4841.9 | Q3: 4841.9 | R3: 4841.9 | S3: 2367.79 | T3: 0 | U3: 0 | V3: 0 | W3: 0 | X3: 0 | Y3: 0 | Z3: 0 | AA3: 0 | AB3: 0 | AC3: 0 | AD3: 0 | AE3: 0 | AF3: 0 | AG3: 0 | AH3: 0 | AI3: 0 | AJ3: 0 | AK3: 0 | AL3: 0 | AM3: 0 | AN3: 0 | AO3: 0 | AP3: 0 | AQ3: 0 | AR3: 0 | AS3: 0 | AT3: 0 | AU3: 0 | AV3: 0 | AW3: 0 | AX3: =SUM(B3:AW3) -> 1268811.9
A4: Giptelecom | C4: 80301.69 | D4: 80301.69 | E4: 80301.69 | F4: 80301.69 | G4: 80301.69 | H4: 80301.69 | I4: 80301.69 | J4: 80301.69 | K4: 80301.69 | L4: 80301.69 | M4: 80301.69 | N4: 80301.69 | O4: 80301.69 | P4: 80301.69 | Q4: 80301.69 | R4: 80301.69 | S4: 80301.69 | T4: 80301.69 | U4: 80301.69 | V4: 80301.69 | W4: 0 | X4: 0 | Y4: 0 | Z4: 0 | AA4: 0 | AB4: 0 | AC4: 0 | AD4: 0 | AE4: 0 | AF4: 0 | AG4: 0 | AH4: 0 | AI4: 0 | AJ4: 0 | AK4: 0 | AL4: 0 | AM4: 0 | AN4: 0 | AO4: 0 | AP4: 0 | AQ4: 0 | AR4: 0 | AS4: 0 | AT4: 0 | AU4: 0 | AV4: 0 | AW4: 0 | AX4: =SUM(B4:AW4) -> 1606033.8
A5: Hilan Telecom Ltda | C5: 279396.23 | D5: 245737.9 | E5: 282396.23 | F5: 245737.9 | G5: 282396.23 | H5: 245737.9 | I5: 282396.23 | J5: 245737.9 | K5: 116658.33 | L5: 0 | M5: 116658.33 | N5: 0 | O5: 116658.37 | P5: 0 | Q5: 0 | R5: 0 | S5: 0 | T5: 0 | U5: 0 | V5: 0 | W5: 0 | X5: 0 | Y5: 0 | Z5: 0 | AA5: 0 | AB5: 0 | AC5: 0 | AD5: 0 | AE5: 0 | AF5: 0 | AG5: 0 | AH5: 0 | AI5: 0 | AJ5: 0 | AK5: 0 | AL5: 0 | AM5: 0 | AN5: 0 | AO5: 0 | AP5: 0 | AQ5: 0 | AR5: 0 | AS5: 0 | AT5: 0 | AU5: 0 | AV5: 0 | AW5: 0 | AX5: =SUM(B5:AW5) -> 2459511.6
A6: Interfiber Telecom Ltda | C6: 57647.1 | D6: 57647.1 | E6: 57647.1 | F6: 57647.1 | G6: 57647.1 | H6: 57647.1 | I6: 57647.1 | J6: 57647.1 | K6: 0 | L6: 0 | M6: 0 | N6: 0 | O6: 0 | P6: 0 | Q6: 0 | R6: 0 | S6: 0 | T6: 0 | U6: 0 | V6: 0 | W6: 0 | X6: 0 | Y6: 0 | Z6: 0 | AA6: 0 | AB6: 0 | AC6: 0 | AD6: 0 | AE6: 0 | AF6: 0 | AG6: 0 | AH6: 0 | AI6: 0 | AJ6: 0 | AK6: 0 | AL6: 0 | AM6: 0 | AN6: 0 | AO6: 0 | AP6: 0 | AQ6: 0 | AR6: 0 | AS6: 0 | AT6: 0 | AU6: 0 | AV6: 0 | AW6: 0 | AX6: =SUM(B6:AW6) -> 461176.8
A7: Total Mensal | B7: =SUM(B2:B6) -> 0 | C7: =SUM(C2:C6) -> 769015.09 | D7: =SUM(D2:D6) -> 852023.42 | E7: =SUM(E2:E6) -> 772015.09 | F7: =SUM(F2:F6) -> 540113.11 | G7: =SUM(G2:G6) -> 460129.28 | H7: =SUM(H2:H6) -> 537811.52 | I7: =SUM(I2:I6) -> 443632.36 | ... AW7: =SUM(AW2:AW6) -> 0 | AX7: =SUM(B7:AW7) -> 6612200.8
